Workbook
Name in_beta_raw: Inputs!$C$10
Name in_capz: Inputs!$C$24
Name in_cash: Inputs!$C$16
Name in_debt_share: Inputs!$C$25
Name in_dep: Inputs!$C$23
Name in_drift: Inputs!$C$21
Name in_ds: Inputs!$C$5
Name in_erp: Inputs!$C$6
Name in_execution: Inputs!$C$19
Name in_g: Inputs!$C$12
Name in_gsec: Inputs!$C$4
Name in_int: Inputs!$C$26
Name in_inv_g: Inputs!$C$30
Name in_kd: Inputs!$C$11
Name in_mi: Inputs!$C$17
Name in_mult: Inputs!$C$18
Name in_oa: Inputs!$C$28
Name in_oi: Inputs!$C$22
Name in_ol: Inputs!$C$29
Name in_payout: Inputs!$C$27
Name in_price: Inputs!$C$14
Name in_ronic: Inputs!$C$13
Name in_shares: Inputs!$C$15
Name in_stub: Inputs!$C$8
Name in_tax: Inputs!$C$7
Name in_w_dcf: Inputs!$C$9
Name in_yield: Inputs!$C$20
Name out_dcf_ps: DCF!$C$34
Name out_rating: DCF!$C$40
Name out_rel_ps: DCF!$C$37
Name out_tp: DCF!$C$38
Name out_upside: DCF!$C$39
Name wacc: DCF!$C$11

Sheet Cover
A1: JSW Energy Ltd
A3: Rating | B3: =DCF!$C$40 -> 0
A4: Target price (Rs) | B4: =DCF!$C$38 -> 0
A5: Current price (Rs) | B5: =Inputs!$C$14 -> 0
A6: Upside | B6: =DCF!$C$39 -> 0
A7: DCF value (Rs) | B7: =DCF!$C$34 -> 0
A8: Peer-multiple value (Rs) | B8: =DCF!$C$37 -> 0
A9: WACC | B9: =DCF!$C$11 -> 0
A11: Blue = input, black = formula. Change Inputs or the capex/margin rows on Model.
A12: Prices as of 2026-09-25. Student research exercise, not investment advice.

Sheet Inputs
A1: JSW Energy Ltd - inputs (Rs crore)
A3: Input | C3: Value | D3: Source / rationale
A4: India 10Y G-sec yield | C4: 0.0711 | D4: Trading Economics, 25-Sep-2026
A5: Sovereign default spread | C5: 0.0187 | D5: Damodaran, Jan-2026 (Baa3)
A6: Equity risk premium (India, total) | C6: 0.0708 | D6: Damodaran, Jan-2026
A7: Tax rate | C7: 0.25 | D7: New corporate regime, 25.17% rounded
A8: FY27 fraction remaining | C8: 0.51 | D8: Valuation date 25-Sep-2026
A9: Weight on DCF in target | C9: 0.5 | D9: Balance on peer EV/EBITDA
A10: Raw beta (2y weekly vs Nifty 50) | C10: 0.805 | D10: Computed from NSE prices
A11: Pre-tax cost of debt | C11: 0.0836 | D11: company-guided WACD
A12: Terminal growth | C12: 0.05 | D12: Nominal INR
A13: Return on new invested capital (terminal) | C13: 0.115 | D13: Cost of debt 8.36% (Q4FY26); RONIC 11.5%.
A14: Share price (Rs) | C14: 506.55 | D14: NSE close 2026-09-25
A15: Shares outstanding (crore) | C15: 183.23729 | D15: NSE / yfinance
... A20: EBITDA yield on commissioned assets | C20: 0.15 | D20: FY26 revenue +61% on the O2 Power and KSK Mahanadi acquisitions; organic growth from 3 GW/yr additions fades as the FY30 target is reached.
A21: EBITDA growth of existing assets | C21: 0.01
A22: Other income % of sales | C22: 0.05
A23: Depreciation % opening net block | C23: 0.06
A24: Capitalisation % of (CWIP + capex) | C24: 0.55
A25: New debt % of capex | C25: 0.65
A26: Interest % average debt | C26: 0.084
A27: Dividend payout | C27: 0.16 | D27: FY26 actual
A28: Other (non-cash) assets % of sales | C28: 1
A29: Other liabilities % of sales | C29: 0.85
A30: Investments growth | C30: 0.05

Sheet Model
A1: JSW Energy Ltd - consolidated model (Rs crore)
C3: FY22A | D3: FY23A | E3: FY24A | F3: FY25A | G3: FY26A | H3: FY27E | I3: FY28E | J3: FY29E | K3: FY30E | L3: FY31E | M3: FY32E | N3: FY33E
A4: Drivers
A5: Capex guided (mgmt) | H5: 20000 | I5: 22000 | J5: 22000 | K5: 22000 | L5: 15000 | M5: 15000 | N5: 15000
A6: EBITDA margin | C6: =C9/C8 -> 0 | D6: =D9/D8 -> 0 | E6: =E9/E8 -> 0 | F6: =F9/F8 -> 0 | G6: =G9/G8 -> 0 | H6: 0.5 | I6: 0.505 | J6: 0.51 | K6: 0.515 | L6: 0.515 | M6: 0.515 | N6: 0.515
A7: Income statement
A8: Revenue | C8: 8167 | D8: 10332 | E8: 11486 | F8: 11745 | G8: 18901 | H8: =H9/H6 -> 0 | I8: =I9/I6 -> 0 | J8: =J9/J6 -> 0 | K8: =K9/K6 -> 0 | L8: =L9/L6 -> 0 | M8: =M9/M6 -> 0 | N8: =N9/N6 -> 0
A9: EBITDA | C9: 3572 | D9: 3282 | E9: 5382 | F9: 5221 | G9: 10068 | H9: =G9*(1+Inputs!$C$21)+Inputs!$C$20*0.5*(G33+H33) -> 0 | I9: =H9*(1+Inputs!$C$21)+Inputs!$C$20*0.5*(H33+I33) -> 0 | J9: =I9*(1+Inputs!$C$21)+Inputs!$C$20*0.5*(I33+J33) -> 0 | K9: =J9*(1+Inputs!$C$21)+Inputs!$C$20*0.5*(J33+K33) -> 0 | L9: =K9*(1+Inputs!$C$21)+Inputs!$C$20*0.5*(K33+L33) -> 0 | M9: =L9*(1+Inputs!$C$21)+Inputs!$C$20*0.5*(L33+M33) -> 0 | N9: =M9*(1+Inputs!$C$21)+Inputs!$C$20*0.5*(M33+N33) -> 0
A10: Other income | C10: 575 | D10: 674 | E10: 472 | F10: 916 | G10: 920 | H10: =H8*Inputs!$C$22 -> 0 | I10: =I8*Inputs!$C$22 -> 0 | J10: =J8*Inputs!$C$22 -> 0 | K10: =K8*Inputs!$C$22 -> 0 | L10: =L8*Inputs!$C$22 -> 0 | M10: =M8*Inputs!$C$22 -> 0 | N10: =N8*Inputs!$C$22 -> 0
A11: Depreciation | C11: 1131 | D11: 1169 | E11: 1633 | F11: 1655 | G11: 3185 | H11: =G19*Inputs!$C$23 -> 0 | I11: =H19*Inputs!$C$23 -> 0 | J11: =I19*Inputs!$C$23 -> 0 | K11: =J19*Inputs!$C$23 -> 0 | L11: =K19*Inputs!$C$23 -> 0 | M11: =L19*Inputs!$C$23 -> 0 | N11: =M19*Inputs!$C$23 -> 0
A12: Interest | C12: 777 | D12: 844 | E12: 2053 | F12: 2269 | G12: 5816 | H12: =(G27+H27)/2*Inputs!$C$26 -> 0 | I12: =(H27+I27)/2*Inputs!$C$26 -> 0 | J12: =(I27+J27)/2*Inputs!$C$26 -> 0 | K12: =(J27+K27)/2*Inputs!$C$26 -> 0 | L12: =(K27+L27)/2*Inputs!$C$26 -> 0 | M12: =(L27+M27)/2*Inputs!$C$26 -> 0 | N12: =(M27+N27)/2*Inputs!$C$26 -> 0
A13: Profit before tax | C13: 2238 | D13: 1943 | E13: 2167 | F13: 2214 | G13: 1986 | H13: =H9+H10-H11-H12 -> 0 | I13: =I9+I10-I11-I12 -> 0 | J13: =J9+J10-J11-J12 -> 0 | K13: =K9+K10-K11-K12 -> 0 | L13: =L9+L10-L11-L12 -> 0 | M13: =M9+M10-M11-M12 -> 0 | N13: =N9+N10-N11-N12 -> 0
A14: Tax | C14: 495 | D14: 463 | E14: 442 | F14: 231 | G14: -776 | H14: =MAX(H13,0)*Inputs!$C$7 -> 0 | I14: =MAX(I13,0)*Inputs!$C$7 -> 0 | J14: =MAX(J13,0)*Inputs!$C$7 -> 0 | K14: =MAX(K13,0)*Inputs!$C$7 -> 0 | L14: =MAX(L13,0)*Inputs!$C$7 -> 0 | M14: =MAX(M13,0)*Inputs!$C$7 -> 0 | N14: =MAX(N13,0)*Inputs!$C$7 -> 0
A15: Net profit | C15: 1743 | D15: 1480 | E15: 1725 | F15: 1983 | G15: 2762 | H15: =H13-H14 -> 0 | I15: =I13-I14 -> 0 | J15: =J13-J14 -> 0 | K15: =K13-K14 -> 0 | L15: =L13-L14 -> 0 | M15: =M13-M14 -> 0 | N15: =N13-N14 -> 0
A16: EPS (Rs) | C16: =C15/Inputs!$C$15 -> 0 | D16: =D15/Inputs!$C$15 -> 0 | E16: =E15/Inputs!$C$15 -> 0 | F16: =F15/Inputs!$C$15 -> 0 | G16: =G15/Inputs!$C$15 -> 0 | H16: =H15/Inputs!$C$15 -> 0 | I16: =I15/Inputs!$C$15 -> 0 | J16: =J15/Inputs!$C$15 -> 0 | ... N16: =N15/Inputs!$C$15 -> 0
A17: Dividends | H17: =MAX(H15,0)*Inputs!$C$27 -> 0 | I17: =MAX(I15,0)*Inputs!$C$27 -> 0 | J17: =MAX(J15,0)*Inputs!$C$27 -> 0 | K17: =MAX(K15,0)*Inputs!$C$27 -> 0 | L17: =MAX(L15,0)*Inputs!$C$27 -> 0 | M17: =MAX(M15,0)*Inputs!$C$27 -> 0 | N17: =MAX(N15,0)*Inputs!$C$27 -> 0
A18: Balance sheet
A19: Net block | C19: 14831 | D19: 25020 | E19: 28946 | F19: 54155 | G19: 74523 | H19: =G19+H33-H11 -> 0 | I19: =H19+I33-I11 -> 0 | J19: =I19+J33-J11 -> 0 | K19: =J19+K33-K11 -> 0 | L19: =K19+L33-L11 -> 0 | M19: =L19+M33-M11 -> 0 | N19: =M19+N33-N11 -> 0
A20: Capital work in progress | C20: 2091 | D20: 4788 | E20: 10285 | F20: 10281 | G20: 17465 | H20: =G20+H32-H33 -> 0 | I20: =H20+I32-I33 -> 0 | J20: =I20+J32-J33 -> 0 | K20: =J20+K32-K33 -> 0 | L20: =K20+L32-L33 -> 0 | M20: =L20+M32-M33 -> 0 | N20: =M20+N32-N33 -> 0
A21: Investments | C21: 6623 | D21: 6033 | E21: 7035 | F21: 9755 | G21: 11379 | H21: =G21*(1+Inputs!$C$30) -> 0 | I21: =H21*(1+Inputs!$C$30) -> 0 | J21: =I21*(1+Inputs!$C$30) -> 0 | K21: =J21*(1+Inputs!$C$30) -> 0 | L21: =K21*(1+Inputs!$C$30) -> 0 | M21: =L21*(1+Inputs!$C$30) -> 0 | N21: =M21*(1+Inputs!$C$30) -> 0
A22: Other assets (non-cash) | C22: 6970 | D22: 12576 | E22: 11501 | F22: 15264 | G22: 20440 | H22: =H8*Inputs!$C$28 -> 0 | I22: =I8*Inputs!$C$28 -> 0 | J22: =J8*Inputs!$C$28 -> 0 | K22: =K8*Inputs!$C$28 -> 0 | L22: =L8*Inputs!$C$28 -> 0 | M22: =M8*Inputs!$C$28 -> 0 | N22: =N8*Inputs!$C$28 -> 0
A23: Cash build from FY26 | G23: 0 | H23: =G23+H36+H37+H38 -> 0 | I23: =H23+I36+I37+I38 -> 0 | J23: =I23+J36+J37+J38 -> 0 | K23: =J23+K36+K37+K38 -> 0 | L23: =K23+L36+L37+L38 -> 0 | M23: =L23+M36+M37+M38 -> 0 | N23: =M23+N36+N37+N38 -> 0
A24: Total assets | C24: =C19+C20+C21+C22 -> 0 | D24: =D19+D20+D21+D22 -> 0 | E24: =E19+E20+E21+E22 -> 0 | F24: =F19+F20+F21+F22 -> 0 | G24: =G19+G20+G21+G22+G23 -> 0 | H24: =H19+H20+H21+H22+H23 -> 0 | I24: =I19+I20+I21+I22+I23 -> 0 | J24: =J19+J20+J21+J22+J23 -> 0 | K24: =K19+K20+K21+K22+K23 -> 0 | L24: =L19+L20+L21+L22+L23 -> 0 | M24: =M19+M20+M21+M22+M23 -> 0 | N24: =N19+N20+N21+N22+N23 -> 0
A25: Equity capital | C25: 1640 | D25: 1641 | E25: 1641 | F25: 1745 | G25: 1756 | H25: =G25 -> 0 | I25: =H25 -> 0 | J25: =I25 -> 0 | K25: =J25 -> 0 | L25: =K25 -> 0 | M25: =L25 -> 0 | N25: =M25 -> 0
A26: Reserves | C26: 15775 | D26: 16988 | E26: 19191 | F26: 25616 | G26: 28995 | H26: =G26+H15-H17 -> 0 | I26: =H26+I15-I17 -> 0 | J26: =I26+J15-J17 -> 0 | K26: =J26+K15-K17 -> 0 | L26: =K26+L15-L17 -> 0 | M26: =L26+M15-M17 -> 0 | N26: =M26+N15-N17 -> 0
A27: Borrowings | C27: 8943 | D27: 25051 | E27: 31573 | F27: 50185 | G27: 76946 | H27: =G27+H32*Inputs!$C$25 -> 0 | I27: =H27+I32*Inputs!$C$25 -> 0 | J27: =I27+J32*Inputs!$C$25 -> 0 | K27: =J27+K32*Inputs!$C$25 -> 0 | L27: =K27+L32*Inputs!$C$25 -> 0 | M27: =L27+M32*Inputs!$C$25 -> 0 | N27: =M27+N32*Inputs!$C$25 -> 0
A28: Other liabilities | C28: 4157 | D28: 4737 | E28: 5362 | F28: 11909 | G28: 16110 | H28: =H8*Inputs!$C$29 -> 0 | I28: =I8*Inputs!$C$29 -> 0 | J28: =J8*Inputs!$C$29 -> 0 | K28: =K8*Inputs!$C$29 -> 0 | L28: =L8*Inputs!$C$29 -> 0 | M28: =M8*Inputs!$C$29 -> 0 | N28: =N8*Inputs!$C$29 -> 0
A29: Total liabilities & equity | C29: =C25+C26+C27+C28 -> 0 | D29: =D25+D26+D27+D28 -> 0 | E29: =E25+E26+E27+E28 -> 0 | F29: =F25+F26+F27+F28 -> 0 | G29: =G25+G26+G27+G28 -> 0 | H29: =H25+H26+H27+H28 -> 0 | I29: =I25+I26+I27+I28 -> 0 | J29: =J25+J26+J27+J28 -> 0 | ... N29: =N25+N26+N27+N28 -> 0
A30: Balance check (assets - liabilities) | C30: =IF(ABS(C24-C29)<2,0,C24-C29) -> 0 | D30: =IF(ABS(D24-D29)<2,0,D24-D29) -> 0 | E30: =IF(ABS(E24-E29)<2,0,E24-E29) -> 0 | F30: =IF(ABS(F24-F29)<2,0,F24-F29) -> 0 | G30: =IF(ABS(G24-G29)<2,0,G24-G29) -> 0 | H30: =ROUND(H24-H29,4) -> 0 | I30: =ROUND(I24-I29,4) -> 0 | J30: =ROUND(J24-J29,4) -> 0 | K30: =ROUND(K24-K29,4) -> 0 | L30: =ROUND(L24-L29,4) -> 0 | M30: =ROUND(M24-M29,4) -> 0 | N30: =ROUND(N24-N29,4) -> 0
A31: Capex and commissioning
A32: Capex | C32: 1943 | D32: 14055 | E32: 11056 | F32: 26860 | G32: 30737 | H32: =H5*Inputs!$C$19 -> 0 | I32: =I5*Inputs!$C$19 -> 0 | J32: =J5*Inputs!$C$19 -> 0 | K32: =K5*Inputs!$C$19 -> 0 | L32: =L5*Inputs!$C$19 -> 0 | M32: =M5*Inputs!$C$19 -> 0 | N32: =N5*Inputs!$C$19 -> 0
A33: Assets commissioned (CWIP to block) | C33: 325 | D33: 11358 | E33: 5559 | F33: 26864 | G33: 23553 | H33: =(G20+H32)*Inputs!$C$24 -> 0 | I33: =(H20+I32)*Inputs!$C$24 -> 0 | J33: =(I20+J32)*Inputs!$C$24 -> 0 | K33: =(J20+K32)*Inputs!$C$24 -> 0 | L33: =(K20+L32)*Inputs!$C$24 -> 0 | M33: =(L20+M32)*Inputs!$C$24 -> 0 | N33: =(M20+N32)*Inputs!$C$24 -> 0
A34: Cash flow
A35: Increase in net working capital | H35: =(H22-H28)-(G22-G28) -> 0 | I35: =(I22-I28)-(H22-H28) -> 0 | J35: =(J22-J28)-(I22-I28) -> 0 | K35: =(K22-K28)-(J22-J28) -> 0 | L35: =(L22-L28)-(K22-K28) -> 0 | M35: =(M22-M28)-(L22-L28) -> 0 | N35: =(N22-N28)-(M22-M28) -> 0
A36: Cash from operations | C36: 2952 | D36: 2084 | E36: 6234 | F36: 3838 | G36: 9898 | H36: =H15+H11-H35 -> 0 | I36: =I15+I11-I35 -> 0 | J36: =J15+J11-J35 -> 0 | K36: =K15+K11-K35 -> 0 | L36: =L15+L11-L35 -> 0 | M36: =M15+M11-M35 -> 0 | N36: =N15+N11-N35 -> 0
A37: Cash from investing | C37: -1387 | D37: -6778 | E37: -8197 | F37: -22990 | G37: -18523 | H37: =-H32-(H21-G21) -> 0 | I37: =-I32-(I21-H21) -> 0 | J37: =-J32-(J21-I21) -> 0 | K37: =-K32-(K21-J21) -> 0 | L37: =-L32-(L21-K21) -> 0 | M37: =-M32-(M21-L21) -> 0 | N37: =-N32-(N21-M21) -> 0
A38: Cash from financing | C38: -781 | D38: 7327 | E38: 1675 | F38: 20223 | G38: 10617 | H38: =(H27-G27)-H17 -> 0 | I38: =(I27-H27)-I17 -> 0 | J38: =(J27-I27)-J17 -> 0 | K38: =(K27-J27)-K17 -> 0 | L38: =(L27-K27)-L17 -> 0 | M38: =(M27-L27)-M17 -> 0 | N38: =(N27-M27)-N17 -> 0
A39: Ratios
A40: Net debt / EBITDA | C40: =C27/C9 -> 0 | D40: =D27/D9 -> 0 | E40: =E27/E9 -> 0 | F40: =F27/F9 -> 0 | G40: =G27/G9 -> 0 | H40: =(H27-H23)/H9 -> 0 | I40: =(I27-I23)/I9 -> 0 | J40: =(J27-J23)/J9 -> 0 | K40: =(K27-K23)/K9 -> 0 | L40: =(L27-L23)/L9 -> 0 | M40: =(M27-M23)/M9 -> 0 | N40: =(N27-N23)/N9 -> 0
A41: Return on average equity | H41: =H15/((H25+H26+G25+G26)/2) -> 0 | I41: =I15/((I25+I26+H25+H26)/2) -> 0 | J41: =J15/((J25+J26+I25+I26)/2) -> 0 | K41: =K15/((K25+K26+J25+J26)/2) -> 0 | L41: =L15/((L25+L26+K25+K26)/2) -> 0 | M41: =M15/((M25+M26+L25+L26)/2) -> 0 | N41: =N15/((N25+N26+M25+M26)/2) -> 0

Sheet DCF
A1: JSW Energy Ltd - valuation
A3: Cost of capital | C3: Value
A4: Risk-free (INR, G-sec less default spread) | C4: =Inputs!$C$4-Inputs!$C$5 -> 0
A5: Beta (Blume-adjusted) | C5: =0.67*Inputs!$C$10+0.33 -> 0
A6: Cost of equity | C6: =$C$4+$C$5*Inputs!$C$6 -> 0
A7: Post-tax cost of debt | C7: =Inputs!$C$11*(1-Inputs!$C$7) -> 0
A8: Borrowings FY26 | C8: =Model!$G$27 -> 0
A9: Market cap | C9: =Inputs!$C$14*Inputs!$C$15 -> 0
A10: Debt weight | C10: =$C$8/($C$8+$C$9) -> 0
A11: WACC | C11: =(1-$C$10)*$C$6+$C$10*$C$7 -> 0
A13: Free cash flow to firm | C13: FY27E | D13: FY28E | E13: FY29E | F13: FY30E | G13: FY31E | H13: FY32E | I13: FY33E
A14: NOPAT | C14: =(Model!$H$9-Model!$H$11)*(1-Inputs!$C$7) -> 0 | D14: =(Model!$I$9-Model!$I$11)*(1-Inputs!$C$7) -> 0 | E14: =(Model!$J$9-Model!$J$11)*(1-Inputs!$C$7) -> 0 | F14: =(Model!$K$9-Model!$K$11)*(1-Inputs!$C$7) -> 0 | G14: =(Model!$L$9-Model!$L$11)*(1-Inputs!$C$7) -> 0 | H14: =(Model!$M$9-Model!$M$11)*(1-Inputs!$C$7) -> 0 | I14: =(Model!$N$9-Model!$N$11)*(1-Inputs!$C$7) -> 0
A15: Depreciation | C15: =Model!$H$11 -> 0 | D15: =Model!$I$11 -> 0 | E15: =Model!$J$11 -> 0 | F15: =Model!$K$11 -> 0 | G15: =Model!$L$11 -> 0 | H15: =Model!$M$11 -> 0 | I15: =Model!$N$11 -> 0
A16: Capex | C16: =-Model!$H$32 -> 0 | D16: =-Model!$I$32 -> 0 | E16: =-Model!$J$32 -> 0 | F16: =-Model!$K$32 -> 0 | G16: =-Model!$L$32 -> 0 | H16: =-Model!$M$32 -> 0 | I16: =-Model!$N$32 -> 0
A17: Increase in NWC | C17: =-Model!$H$35 -> 0 | D17: =-Model!$I$35 -> 0 | E17: =-Model!$J$35 -> 0 | F17: =-Model!$K$35 -> 0 | G17: =-Model!$L$35 -> 0 | H17: =-Model!$M$35 -> 0 | I17: =-Model!$N$35 -> 0
A18: FCFF | C18: =SUM(C14:C17) -> 0 | D18: =SUM(D14:D17) -> 0 | E18: =SUM(E14:E17) -> 0 | F18: =SUM(F14:F17) -> 0 | G18: =SUM(G14:G17) -> 0 | H18: =SUM(H14:H17) -> 0 | I18: =SUM(I14:I17) -> 0
A19: FCFF (stub-adjusted) | C19: =C18*Inputs!$C$8 -> 0 | D19: =D18*1 -> 0 | E19: =E18*1 -> 0 | F19: =F18*1 -> 0 | G19: =G18*1 -> 0 | H19: =H18*1 -> 0 | I19: =I18*1 -> 0
A20: Discount period (yrs) | C20: =Inputs!$C$8+0 -> 0 | D20: =Inputs!$C$8+1 -> 0 | E20: =Inputs!$C$8+2 -> 0 | F20: =Inputs!$C$8+3 -> 0 | G20: =Inputs!$C$8+4 -> 0 | H20: =Inputs!$C$8+5 -> 0 | I20: =Inputs!$C$8+6 -> 0
A21: Discount factor | C21: =1/(1+DCF!$C$11)^C20 -> 0 | D21: =1/(1+DCF!$C$11)^D20 -> 0 | E21: =1/(1+DCF!$C$11)^E20 -> 0 | F21: =1/(1+DCF!$C$11)^F20 -> 0 | G21: =1/(1+DCF!$C$11)^G20 -> 0 | H21: =1/(1+DCF!$C$11)^H20 -> 0 | I21: =1/(1+DCF!$C$11)^I20 -> 0
A22: PV of FCFF | C22: =C19*C21 -> 0 | D22: =D19*D21 -> 0 | E22: =E19*E21 -> 0 | F22: =F19*F21 -> 0 | G22: =G19*G21 -> 0 | H22: =H19*H21 -> 0 | I22: =I19*I21 -> 0
A25: PV of explicit FCFF | C25: =SUM(C22:I22) -> 0
A26: Terminal value (value-driver) | C26: =I14*(1+Inputs!$C$12)*(1-Inputs!$C$12/Inputs!$C$13)/(DCF!$C$11-Inputs!$C$12) -> 0
A27: PV of terminal value | C27: =$C$26/(1+DCF!$C$11)^I20 -> 0
A28: Enterprise value | C28: =$C$25+$C$27 -> 0
A29: Less: borrowings FY26 | C29: =-Model!$G$27 -> 0
A30: Add: cash | C30: =Inputs!$C$16 -> 0
A31: Add: investments (book) | C31: =Model!$G$21 -> 0
A32: Less: minority interest | C32: =-Inputs!$C$17 -> 0
A33: Equity value | C33: =SUM($C$28,$C$29,$C$30,$C$31,$C$32) -> 0
A34: DCF value per share (Rs) | C34: =$C$33/Inputs!$C$15 -> 0
A35: Terminal value share of EV | C35: =$C$27/$C$28 -> 0
A36: Peer EV/EBITDA x FY26A EBITDA | C36: =Inputs!$C$18*Model!$G$9 -> 0
A37: Relative value per share (Rs) | C37: =($C$36-Model!$G$27+Inputs!$C$16-Inputs!$C$17)/Inputs!$C$15 -> 0
A38: Target price (Rs) | C38: =Inputs!$C$9*$C$34+(1-Inputs!$C$9)*$C$37 -> 0
A39: Upside / (downside) | C39: =$C$38/Inputs!$C$14-1 -> 0
A40: Rating | C40: =IF($C$39>0.15,"BUY",IF($C$39<-0.1,"SELL","HOLD")) -> 0
A43: DCF value per share: WACC (rows) x terminal growth (cols)
C44: 0.04 | D44: 0.045 | E44: 0.05 | F44: 0.055 | G44: 0.06
B45: =DCF!$C$11+-0.01 -> 0 | C45: =(SUMPRODUCT($C$19:$I$19/(1+$B45)^$C$20:$I$20)+$I$14*(1+C$44)*(1-C$44/Inputs!$C$13)/($B45-C$44)/(1+$B45)^$I$20-Model!$G$27+Inputs!$C$16+Model!$G$21-Inputs!$C$17)/Inputs!$C$15 -> 0 | D45: =(SUMPRODUCT($C$19:$I$19/(1+$B45)^$C$20:$I$20)+$I$14*(1+D$44)*(1-D$44/Inputs!$C$13)/($B45-D$44)/(1+$B45)^$I$20-Model!$G$27+Inputs!$C$16+Model!$G$21-Inputs!$C$17)/Inputs!$C$15 -> 0 | E45: =(SUMPRODUCT($C$19:$I$19/(1+$B45)^$C$20:$I$20)+$I$14*(1+E$44)*(1-E$44/Inputs!$C$13)/($B45-E$44)/(1+$B45)^$I$20-Model!$G$27+Inputs!$C$16+Model!$G$21-Inputs!$C$17)/Inputs!$C$15 -> 0 | F45: =(SUMPRODUCT($C$19:$I$19/(1+$B45)^$C$20:$I$20)+$I$14*(1+F$44)*(1-F$44/Inputs!$C$13)/($B45-F$44)/(1+$B45)^$I$20-Model!$G$27+Inputs!$C$16+Model!$G$21-Inputs!$C$17)/Inputs!$C$15 -> 0 | G45: =(SUMPRODUCT($C$19:$I$19/(1+$B45)^$C$20:$I$20)+$I$14*(1+G$44)*(1-G$44/Inputs!$C$13)/($B45-G$44)/(1+$B45)^$I$20-Model!$G$27+Inputs!$C$16+Model!$G$21-Inputs!$C$17)/Inputs!$C$15 -> 0
B46: =DCF!$C$11+-0.005 -> 0 | C46: =(SUMPRODUCT($C$19:$I$19/(1+$B46)^$C$20:$I$20)+$I$14*(1+C$44)*(1-C$44/Inputs!$C$13)/($B46-C$44)/(1+$B46)^$I$20-Model!$G$27+Inputs!$C$16+Model!$G$21-Inputs!$C$17)/Inputs!$C$15 -> 0 | D46: =(SUMPRODUCT($C$19:$I$19/(1+$B46)^$C$20:$I$20)+$I$14*(1+D$44)*(1-D$44/Inputs!$C$13)/($B46-D$44)/(1+$B46)^$I$20-Model!$G$27+Inputs!$C$16+Model!$G$21-Inputs!$C$17)/Inputs!$C$15 -> 0 | E46: =(SUMPRODUCT($C$19:$I$19/(1+$B46)^$C$20:$I$20)+$I$14*(1+E$44)*(1-E$44/Inputs!$C$13)/($B46-E$44)/(1+$B46)^$I$20-Model!$G$27+Inputs!$C$16+Model!$G$21-Inputs!$C$17)/Inputs!$C$15 -> 0 | F46: =(SUMPRODUCT($C$19:$I$19/(1+$B46)^$C$20:$I$20)+$I$14*(1+F$44)*(1-F$44/Inputs!$C$13)/($B46-F$44)/(1+$B46)^$I$20-Model!$G$27+Inputs!$C$16+Model!$G$21-Inputs!$C$17)/Inputs!$C$15 -> 0 | G46: =(SUMPRODUCT($C$19:$I$19/(1+$B46)^$C$20:$I$20)+$I$14*(1+G$44)*(1-G$44/Inputs!$C$13)/($B46-G$44)/(1+$B46)^$I$20-Model!$G$27+Inputs!$C$16+Model!$G$21-Inputs!$C$17)/Inputs!$C$15 -> 0
...

Sheet Comps
A1: Listed power comps, FY26A
A3: Company | B3: Segment | C3: Mcap | D3: EV | E3: EV/EBITDA | F3: P/E | G3: P/B | H3: ROE | I3: EBITDA margin | J3: ND/EBITDA
A4: Adani Power | B4: IPP / thermal | C4: 390997.19 | D4: 444740.67 | E4: 22.454845 | F4: 30.143951 | G4: 6.0211772 | H4: 0.21389466 | I4: 0.36514814 | J4: 2.6395254
A5: NTPC Ltd | B5: Integrated / thermal-led | C5: 316693.12 | D5: 589225.83 | E5: 10.628555 | F5: 11.496882 | G5: 1.5587132 | H5: 0.14226579 | I5: 0.29585079 | J5: 4.7720935
A6: Power Grid Corp | B6: Transmission / PSU | C6: 250651.27 | D6: 393788.96 | E6: 11.994425 | F6: 15.736519 | G6: 2.4941914 | H6: 0.16492283 | I6: 0.70252284 | J6: 4.3598334
A7: Adani Green Energy | B7: Renewables | C7: 213572.86 | D7: 322958.86 | E7: 29.945189 | F7: 107.48508 | G7: 10.697363 | H7: 0.12379291 | I7: 0.83423577 | J7: 9.2231803
A8: Tata Power | B8: Integrated / private | C8: 117428.73 | D8: 195874.8 | E8: 14.759611 | F8: 22.944261 | G8: 2.9752896 | H8: 0.13592001 | I8: 0.21257749 | J8: 5.302932
A9: JSW Energy | B9: IPP / private | C9: 92818.851 | D9: 164481.69 | E9: 16.337077 | F9: 33.605667 | G9: 3.0184011 | H9: 0.095057819 | I9: 0.53267023 | J9: 6.837206
A10: NHPC | B10: Hydro / PSU | C10: 76342.265 | D10: 132109.38 | E10: 32.245395 | F10: 18.090584 | G10: 1.8423695 | H10: 0.10406263 | I10: 0.35273353 | J10: 11.91102
A11: Torrent Power | B11: Integrated / private | C11: 63219.739 | D11: 75504.749 | E11: 13.538596 | F11: 25.605402 | G11: 3.314272 | H11: 0.13458708 | I11: 0.19253608 | J11: 2.0892218
A12: NLC India | B12: Lignite-thermal / PSU | C12: 36406.144 | D12: 67334.034 | E12: 12.114796 | F12: 9.6593643 | G12: 1.6913424 | H12: 0.18728881 | I12: 0.31725555 | J12: 4.8900036
A13: SJVN | B13: Hydro / PSU | C13: 24270.415 | D13: 54422.845 | E13: 16.192456 | F13: 37.804385 | G13: 1.7045028 | H13: 0.045182631 | I13: 0.74227032 | J13: 8.9681791
A14: CESC | B14: Integrated / private | C14: 18539.428 | D14: 35265.428 | E14: 9.7310784 | F14: 11.458237 | G14: 1.4796032 | H14: 0.13186634 | I14: 0.19515347 | J14: 4.4336341
A15: JP Power Ventures | B15: IPP / thermal | C15: 10876.439 | D15: 13512.489 | E15: 9.8847763 | F15: 24.116273 | G15: 0.85426007 | H15: 0.036061248 | I15: 0.24573072 | J15: 1.9283467
A16: Reliance Power | B16: IPP / thermal | C16: 8507.2809 | D16: 22815.031 | E16: 9.6469475 | G16: 0.53037911 | H16: -0.020817247 | I16: 0.31036745 | J16: 6.0497886
A17: PTC India | B17: Power trading | C17: 4590.7931 | D17: 2852.3531 | E17: 3.1977052 | F17: 6.4027797 | G17: 0.76756279 | H17: 0.12166978 | I17: 0.053187049 | J17: -3.1571973

Sheet Guidance
A1: Management guidance extracted from earnings calls (NSE filings)
A3: Call | B3: Page | C3: Figures | D3: Sentence
A4: Q1FY27 | B4: 3 | C4: 150 MW; 22 Crore | D4: The 150 MW was driven by the early commissioning of Tidong Hydro, originally scheduled for October 2026, which contributed an incremental ₹20-22 Crore to EBITDA in Q1 itself and will allow us to capture the ongoing hydrology season.
A5: Q1FY27 | B5: 7 | C5: 600 MW | D5: My second question on the thermal space is you have introduced 600 MW Mahanadi under under construction projects now.
A6: Q1FY27 | B6: 17 | C6: 85% | D6: Sharad Mahendra: If you look at Mahanadi, the plant availability entitlement is considered over the entire year and is around 85%.
A7: Q1FY27 | B7: 16 | C7: 3 GW | D7: Rajesh Majumdar: And next year also, we plan to add about 3 GW or similar?
A8: Q1FY27 | B8: 16 | C8: 20,000 crore | D8: And if we look at it, you talked about ₹ 20,000 crores capex for the year.
A9: Q1FY27 | B9: 14 | C9: 80% | D9: So there also, it was again a plant shutdown to ensure the annual availability we have to ensure we achieve of 80% so that's my fixed cost.
A10: Q1FY27 | B10: 12 | C10: 25%; 30%; 1,800 MW; 3,600 MW | D10: As compared to that, Mahanadi, when we will be completing, I can say definitely that we will be at least 25% to 30% lower while doubling the capacity from 1,800 MW to 3,600 MW.
A11: Q1FY27 | B11: 10 | C11: 1,900 MW; 3 GW; 100% | D11: But whatever 1,900 MW we have to commission to reach the 3 GW guidance we have given, we are absolutely 100% secured from connectivity and which is all commissioned also.
A12: Q1FY27 | B12: 10 | C12: 1.9 GW; 28%; 1.9 GW; 530 MW; 1.9 GW | D12: Now, balance 1.9 GW, which we have to commission in this year, I just want to tell you that out of this 28% of the capacity of 1.9 GW, what we are doing, maybe more than 530 MW of balance 1.9 GW, which we have to execute, is our group captive, which is a mix of off grid also.
A13: Q1FY27 | B13: 10 | C13: 1.1 GW | D13: As I said, till date, in the current year since April 1, we have commissioned 1.1 GW of fresh capacity.
A14: Q1FY27 | B14: 9 | C14: 600 MW | D14: But to remember, even if it is merchant, with next to the mine and the coal cost being so low, the cost at which we will be completing this project, another 600 MW, will be significantly lower than the benchmark per MW cost of capacity addition, I think this will remain attractive in both the ways, whether it is merchant or whether it is in long-term PPA.
A15: Q1FY27 | B15: 8 | C15: 800 MW | D15: But we are totally de-risked in terms of the supply chain of boiler, turbine, generators for all our 800 MW expansion plants.
... A153: Q4FY25 | B153: 17 | C153: 1.9 gigawatt | D153: And sir can you just give us a timeline as to what will be the commissioning trend for the rest of the 1.9 gigawatt hours of project?
