Workbook
Name in_beta_raw: Inputs!$C$11
Name in_capz: Inputs!$C$32
Name in_cash: Inputs!$C$17
Name in_debt_share: Inputs!$C$33
Name in_dep: Inputs!$C$31
Name in_ds: Inputs!$C$5
Name in_erp: Inputs!$C$6
Name in_execution: Inputs!$C$20
Name in_g: Inputs!$C$13
Name in_gsec: Inputs!$C$4
Name in_holdco: Inputs!$C$46
Name in_int: Inputs!$C$34
Name in_inv_g: Inputs!$C$38
Name in_jv0: Inputs!$C$28
Name in_jv_g: Inputs!$C$29
Name in_kd: Inputs!$C$12
Name in_mi: Inputs!$C$18
Name in_min_cash: Inputs!$C$10
Name in_mult: Inputs!$C$19
Name in_ngel_mcap: Inputs!$C$44
Name in_ngel_stake: Inputs!$C$45
Name in_oa: Inputs!$C$36
Name in_oi: Inputs!$C$30
Name in_ol: Inputs!$C$37
Name in_payout: Inputs!$C$35
Name in_pb_g: Inputs!$C$43
Name in_price: Inputs!$C$15
Name in_re_cost: Inputs!$C$22
Name in_re_cuf: Inputs!$C$23
Name in_re_margin: Inputs!$C$25
Name in_re_mw0: Inputs!$C$27
Name in_re_mw_prev: Inputs!$C$26
Name in_re_share: Inputs!$C$21
Name in_re_tariff: Inputs!$C$24
Name in_regeq0: Inputs!$C$40
Name in_regeq_prev: Inputs!$C$39
Name in_regshare: Inputs!$C$41
Name in_roe: Inputs!$C$42
Name in_ronic: Inputs!$C$14
Name in_shares: Inputs!$C$16
Name in_stub: Inputs!$C$8
Name in_tax: Inputs!$C$7
Name in_w_dcf: Inputs!$C$9
Name out_dcf_12m: DCF!$C$36
Name out_dcf_ps: DCF!$C$34
Name out_rating: DCF!$C$42
Name out_rel_ps: DCF!$C$38
Name out_sotp_ps: DCF!$C$39
Name out_tp: DCF!$C$40
Name out_upside: DCF!$C$41
Name wacc: DCF!$C$11

Sheet Cover
A1: NTPC Ltd
A3: Rating | B3: =DCF!$C$42 -> 0
A4: 12-month target price (Rs) | B4: =DCF!$C$40 -> 0
A5: Current price (Rs) | B5: =Inputs!$C$15 -> 0
A6: Upside | B6: =DCF!$C$41 -> 0
A7: SOTP value (Rs) | B7: =DCF!$C$39 -> 0
A8: DCF value today (Rs) | B8: =DCF!$C$34 -> 0
A9: DCF value in 12m (Rs) | B9: =DCF!$C$36 -> 0
A10: FY27E EV/EBITDA value (Rs) | B10: =DCF!$C$38 -> 0
A11: WACC | B11: =DCF!$C$11 -> 0
A13: Method: sum of the parts; DCF and EV/EBITDA are cross-checks.
A14: Blue = input, black = formula. Change Inputs or the guided-capex row on Model.
A15: Prices as of 2026-08-14. Student research exercise, not investment advice.

Sheet Inputs
A1: NTPC Ltd - inputs (Rs crore)
A3: Input | C3: Value | D3: Source / rationale
A4: India 10Y G-sec yield | C4: 0.06762 | D4: Investing.com historical close, 14-Aug-2026
A5: Sovereign default spread | C5: 0.0187 | D5: Damodaran, Jan-2026 (Baa3)
A6: Equity risk premium (India, total) | C6: 0.0708 | D6: Damodaran, Jan-2026
A7: Tax rate | C7: 0.25 | D7: New corporate regime, 25.17% rounded
A8: FY27 fraction remaining | C8: 0.62739726 | D8: Valuation date 14-Aug-2026
A9: Weight on 12m DCF in target (non-regulated) | C9: 0.5 | D9: Balance on FY27E EV/EBITDA
A10: Incremental cash floor | C10: 0 | D10: Shortfalls drawn on a revolver
A11: Raw beta (2y weekly vs Nifty 50) | C11: 0.879 | D11: Computed from NSE prices
A12: Pre-tax cost of debt | C12: 0.074 | D12: AAA PSU
A13: Terminal growth | C13: 0.05 | D13: Nominal INR
A14: Return on new invested capital (terminal) | C14: 0.12
A15: Share price (Rs) | C15: 336.37 | D15: NSE close 2026-08-14
A16: Shares outstanding (crore) | C16: 969.66661 | D16: NSE / yfinance
A17: Cash & short-term investments FY26 | C17: 6449.68 | D17: FY26 balance sheet
A18: Minority interest FY26 | C18: 7977.39 | D18: FY26 balance sheet
A19: Peer median EV/EBITDA FY26A | C19: 14.608247 | D19: Peers: NHPC, SJVN, NLCINDIA, POWERGRID
A20: Capex execution vs guidance | C20: 0.7 | D20: Q1FY27 call: group capex Rs 1,08,000 cr for FY27, Rs 5,97,000 cr over FY28-32 (Rs 1,19,400 cr/yr) and Rs 9,63,000 cr over FY33-37, mostly nuclear. FY26 actual was Rs 49,068 cr, so the step-up is haircut to 70%. FY33-36 is held at the FY28-32 run-rate because long-gestation nuclear capex adds little EBITDA in the horizon.
A21: RE share of assets commissioned | C21: 0.5 | D21: Group RE 11,578 MW at Mar-26 (12,068 MW incl. 490 MW added in FY27, Q4FY26 call); NGEL generated 14.6 BU in FY26 (implied CUF ~18.5%) on TTM revenue of Rs 3,285 cr (~Rs 2.25/kWh). NGEL capex Rs 35,800 cr for ~8 GW (Rs 4.5 cr/MW); about half of group capex goes to RE (Q4FY26 call). At guided capex the model commissions ~7 GW of RE in FY27 vs 7-8 GW guided.
A22: RE cost (Rs cr per MW) | C22: 4.5
A23: RE capacity utilisation (CUF) | C23: 0.185
A24: RE tariff (Rs/kWh) | C24: 2.3
A25: RE EBITDA margin | C25: 0.85
A26: RE MW at FY25 (for FY26 calibration) | C26: 6840
A27: RE MW at FY26 | C27: 11578 | D27: NTPC: reported; others: FY26 RE commissioning / cost per MW
A28: Share of JV profit FY26 | C28: 2864 | D28: Q4FY26 call
A29: JV profit growth | C29: 0.05
A30: Other income % of sales | C30: 0.025
A31: Depreciation % opening net block | C31: 0.07
A32: Capitalisation % of (CWIP + capex) | C32: 0.4
A33: New term debt % of capex | C33: 0.5
A34: Interest % average debt (and revolver) | C34: 0.055
A35: Dividend payout | C35: 0.32 | D35: FY26 actual
A36: Other (non-cash) assets % of sales | C36: 0.7
A37: Other liabilities (ex minorities) % of sales | C37: 0.41
A38: Investments growth (cash) | C38: 0.05
A39: Regulated equity FY25 | C39: 108791 | D39: Consolidated regulated equity Rs 1,20,319 cr at Mar-26 vs Rs 1,08,791 cr a year earlier (Q4FY26 call); regulated RoE 15.5% post-tax (CMD, Q1FY27).
A40: Regulated equity FY26 | C40: 120319
A41: Normative equity share of regulated capital | C41: 0.3 | D41: CERC
...

Sheet Model
A1: NTPC Ltd - consolidated model (Rs crore)
C3: FY22A | D3: FY23A | E3: FY24A | F3: FY25A | G3: FY26A | H3: FY27E | I3: FY28E | J3: FY29E | K3: FY30E | L3: FY31E | M3: FY32E | N3: FY33E | O3: FY34E | P3: FY35E | Q3: FY36E
A4: Capex and commissioning
A5: Capex guided (mgmt) | H5: 108000 | I5: 119400 | J5: 119400 | K5: 119400 | L5: 119400 | M5: 119400 | N5: 119400 | O5: 119400 | P5: 119400 | Q5: 119400
A6: Capex | C6: 29086 | D6: 28346 | E6: 33199 | F6: 43099 | G6: 50987 | H6: =H5*Inputs!$C$20 -> 0 | I6: =I5*Inputs!$C$20 -> 0 | J6: =J5*Inputs!$C$20 -> 0 | K6: =K5*Inputs!$C$20 -> 0 | L6: =L5*Inputs!$C$20 -> 0 | M6: =M5*Inputs!$C$20 -> 0 | N6: =N5*Inputs!$C$20 -> 0 | O6: =O5*Inputs!$C$20 -> 0 | ... Q6: =Q5*Inputs!$C$20 -> 0
A7: Assets commissioned (CWIP to block) | C7: 35466 | D7: 30293 | E7: 34714 | F7: 29904 | G7: 66889 | H7: =(G33+H6)*Inputs!$C$32 -> 0 | I7: =(H33+I6)*Inputs!$C$32 -> 0 | J7: =(I33+J6)*Inputs!$C$32 -> 0 | K7: =(J33+K6)*Inputs!$C$32 -> 0 | L7: =(K33+L6)*Inputs!$C$32 -> 0 | M7: =(L33+M6)*Inputs!$C$32 -> 0 | N7: =(M33+N6)*Inputs!$C$32 -> 0 | O7: =(N33+O6)*Inputs!$C$32 -> 0 | ... Q7: =(P33+Q6)*Inputs!$C$32 -> 0
A8: of which renewables | G8: =G7*Inputs!$C$21 -> 0 | H8: =H7*Inputs!$C$21 -> 0 | I8: =I7*Inputs!$C$21 -> 0 | J8: =J7*Inputs!$C$21 -> 0 | K8: =K7*Inputs!$C$21 -> 0 | L8: =L7*Inputs!$C$21 -> 0 | M8: =M7*Inputs!$C$21 -> 0 | N8: =N7*Inputs!$C$21 -> 0 | ... Q8: =Q7*Inputs!$C$21 -> 0
A9: of which core / regulated | G9: =G7-G8 -> 0 | H9: =H7-H8 -> 0 | I9: =I7-I8 -> 0 | J9: =J7-J8 -> 0 | K9: =K7-K8 -> 0 | L9: =L7-L8 -> 0 | M9: =M7-M8 -> 0 | N9: =N7-N8 -> 0 | ... Q9: =Q7-Q8 -> 0
A10: EBITDA build
A11: Renewable capacity (MW) | G11: =Inputs!$C$27 -> 0 | H11: =G11+H8/Inputs!$C$22 -> 0 | I11: =H11+I8/Inputs!$C$22 -> 0 | J11: =I11+J8/Inputs!$C$22 -> 0 | K11: =J11+K8/Inputs!$C$22 -> 0 | L11: =K11+L8/Inputs!$C$22 -> 0 | M11: =L11+M8/Inputs!$C$22 -> 0 | N11: =M11+N8/Inputs!$C$22 -> 0 | O11: =N11+O8/Inputs!$C$22 -> 0 | ... Q11: =P11+Q8/Inputs!$C$22 -> 0
A12: Renewable revenue | G12: =(Inputs!$C$26+Inputs!$C$27)/2*Inputs!$C$23*0.876*Inputs!$C$24 -> 0 | H12: =(G11+H11)/2*Inputs!$C$23*0.876*Inputs!$C$24 -> 0 | I12: =(H11+I11)/2*Inputs!$C$23*0.876*Inputs!$C$24 -> 0 | J12: =(I11+J11)/2*Inputs!$C$23*0.876*Inputs!$C$24 -> 0 | K12: =(J11+K11)/2*Inputs!$C$23*0.876*Inputs!$C$24 -> 0 | L12: =(K11+L11)/2*Inputs!$C$23*0.876*Inputs!$C$24 -> 0 | M12: =(L11+M11)/2*Inputs!$C$23*0.876*Inputs!$C$24 -> 0 | N12: =(M11+N11)/2*Inputs!$C$23*0.876*Inputs!$C$24 -> 0 | O12: =(N11+O11)/2*Inputs!$C$23*0.876*Inputs!$C$24 -> 0 | ... Q12: =(P11+Q11)/2*Inputs!$C$23*0.876*Inputs!$C$24 -> 0
A13: Renewable EBITDA | G13: =G12*Inputs!$C$25 -> 0 | H13: =H12*Inputs!$C$25 -> 0 | I13: =I12*Inputs!$C$25 -> 0 | J13: =J12*Inputs!$C$25 -> 0 | K13: =K12*Inputs!$C$25 -> 0 | L13: =L12*Inputs!$C$25 -> 0 | M13: =M12*Inputs!$C$25 -> 0 | N13: =N12*Inputs!$C$25 -> 0 | ... Q13: =Q12*Inputs!$C$25 -> 0
A14: Regulated equity | G14: =Inputs!$C$40 -> 0 | H14: =G14+Inputs!$C$41*H9 -> 0 | I14: =H14+Inputs!$C$41*I9 -> 0 | J14: =I14+Inputs!$C$41*J9 -> 0 | K14: =J14+Inputs!$C$41*K9 -> 0 | L14: =K14+Inputs!$C$41*L9 -> 0 | M14: =L14+Inputs!$C$41*M9 -> 0 | N14: =M14+Inputs!$C$41*N9 -> 0 | O14: =N14+Inputs!$C$41*O9 -> 0 | ... Q14: =P14+Inputs!$C$41*Q9 -> 0
A15: Regulated (core) EBITDA | G15: =G16-G13 -> 0 | H15: =$G$15*(G14+H14)/2/((Inputs!$C$39+Inputs!$C$40)/2) -> 0 | I15: =$G$15*(H14+I14)/2/((Inputs!$C$39+Inputs!$C$40)/2) -> 0 | J15: =$G$15*(I14+J14)/2/((Inputs!$C$39+Inputs!$C$40)/2) -> 0 | K15: =$G$15*(J14+K14)/2/((Inputs!$C$39+Inputs!$C$40)/2) -> 0 | L15: =$G$15*(K14+L14)/2/((Inputs!$C$39+Inputs!$C$40)/2) -> 0 | M15: =$G$15*(L14+M14)/2/((Inputs!$C$39+Inputs!$C$40)/2) -> 0 | N15: =$G$15*(M14+N14)/2/((Inputs!$C$39+Inputs!$C$40)/2) -> 0 | O15: =$G$15*(N14+O14)/2/((Inputs!$C$39+Inputs!$C$40)/2) -> 0 | ... Q15: =$G$15*(P14+Q14)/2/((Inputs!$C$39+Inputs!$C$40)/2) -> 0
A16: EBITDA | C16: 40362 | D16: 47596 | E16: 51469 | F16: 54355 | G16: 55438 | H16: =H15+H13 -> 0 | I16: =I15+I13 -> 0 | J16: =J15+J13 -> 0 | K16: =K15+K13 -> 0 | L16: =L15+L13 -> 0 | M16: =M15+M13 -> 0 | N16: =N15+N13 -> 0 | O16: =O15+O13 -> 0 | ... Q16: =Q15+Q13 -> 0
A17: EBITDA margin | C17: =C16/C19 -> 0 | D17: =D16/D19 -> 0 | E17: =E16/E19 -> 0 | F17: =F16/F19 -> 0 | G17: =G16/G19 -> 0 | H17: =H16/H19 -> 0 | I17: =I16/I19 -> 0 | J17: =J16/J19 -> 0 | ... Q17: =Q16/Q19 -> 0
A18: Income statement
A19: Revenue | C19: 132669 | D19: 176207 | E19: 178525 | F19: 188138 | G19: 187385 | H19: =H15/($G$15/($G$19-$G$12))+H12 -> 0 | I19: =I15/($G$15/($G$19-$G$12))+I12 -> 0 | J19: =J15/($G$15/($G$19-$G$12))+J12 -> 0 | K19: =K15/($G$15/($G$19-$G$12))+K12 -> 0 | L19: =L15/($G$15/($G$19-$G$12))+L12 -> 0 | M19: =M15/($G$15/($G$19-$G$12))+M12 -> 0 | N19: =N15/($G$15/($G$19-$G$12))+N12 -> 0 | O19: =O15/($G$15/($G$19-$G$12))+O12 -> 0 | ... Q19: =Q15/($G$15/($G$19-$G$12))+Q12 -> 0
A20: Other income | C20: 4809 | D20: 2561 | E20: 5177 | F20: 8526 | G20: 2662 | H20: =H19*Inputs!$C$30 -> 0 | I20: =I19*Inputs!$C$30 -> 0 | J20: =J19*Inputs!$C$30 -> 0 | K20: =K19*Inputs!$C$30 -> 0 | L20: =L19*Inputs!$C$30 -> 0 | M20: =M19*Inputs!$C$30 -> 0 | N20: =N19*Inputs!$C$30 -> 0 | O20: =O19*Inputs!$C$30 -> 0 | ... Q20: =Q19*Inputs!$C$30 -> 0
A21: Depreciation | C21: 13788 | D21: 14792 | E21: 16204 | F21: 17401 | G21: 19629 | H21: =G32*Inputs!$C$31 -> 0 | I21: =H32*Inputs!$C$31 -> 0 | J21: =I32*Inputs!$C$31 -> 0 | K21: =J32*Inputs!$C$31 -> 0 | L21: =K32*Inputs!$C$31 -> 0 | M21: =L32*Inputs!$C$31 -> 0 | N21: =M32*Inputs!$C$31 -> 0 | O21: =N32*Inputs!$C$31 -> 0 | ... Q21: =P32*Inputs!$C$31 -> 0
A22: Interest (term debt + opening revolver) | C22: 9376 | D22: 11447 | E22: 12301 | F22: 13282 | G22: 13801 | H22: =(G41+H41)/2*Inputs!$C$34+G42*Inputs!$C$34 -> 0 | I22: =(H41+I41)/2*Inputs!$C$34+H42*Inputs!$C$34 -> 0 | J22: =(I41+J41)/2*Inputs!$C$34+I42*Inputs!$C$34 -> 0 | K22: =(J41+K41)/2*Inputs!$C$34+J42*Inputs!$C$34 -> 0 | L22: =(K41+L41)/2*Inputs!$C$34+K42*Inputs!$C$34 -> 0 | M22: =(L41+M41)/2*Inputs!$C$34+L42*Inputs!$C$34 -> 0 | N22: =(M41+N41)/2*Inputs!$C$34+M42*Inputs!$C$34 -> 0 | O22: =(N41+O41)/2*Inputs!$C$34+N42*Inputs!$C$34 -> 0 | ... Q22: =(P41+Q41)/2*Inputs!$C$34+P42*Inputs!$C$34 -> 0
A23: Profit before tax | C23: 22007 | D23: 23917 | E23: 28142 | F23: 32198 | G23: 24669 | H23: =H16+H20-H21-H22 -> 0 | I23: =I16+I20-I21-I22 -> 0 | J23: =J16+J20-J21-J22 -> 0 | K23: =K16+K20-K21-K22 -> 0 | L23: =L16+L20-L21-L22 -> 0 | M23: =M16+M20-M21-M22 -> 0 | N23: =N16+N20-N21-N22 -> 0 | O23: =O16+O20-O21-O22 -> 0 | ... Q23: =Q16+Q20-Q21-Q22 -> 0
A24: Tax | C24: 5047 | D24: 6796 | E24: 6810 | F24: 8245 | G24: -2877 | H24: =MAX(H23,0)*Inputs!$C$7 -> 0 | I24: =MAX(I23,0)*Inputs!$C$7 -> 0 | J24: =MAX(J23,0)*Inputs!$C$7 -> 0 | K24: =MAX(K23,0)*Inputs!$C$7 -> 0 | L24: =MAX(L23,0)*Inputs!$C$7 -> 0 | M24: =MAX(M23,0)*Inputs!$C$7 -> 0 | N24: =MAX(N23,0)*Inputs!$C$7 -> 0 | O24: =MAX(O23,0)*Inputs!$C$7 -> 0 | ... Q24: =MAX(Q23,0)*Inputs!$C$7 -> 0
A25: Share of JV profit | G25: =Inputs!$C$28 -> 0 | H25: =G25*(1+Inputs!$C$29) -> 0 | I25: =H25*(1+Inputs!$C$29) -> 0 | J25: =I25*(1+Inputs!$C$29) -> 0 | K25: =J25*(1+Inputs!$C$29) -> 0 | L25: =K25*(1+Inputs!$C$29) -> 0 | M25: =L25*(1+Inputs!$C$29) -> 0 | N25: =M25*(1+Inputs!$C$29) -> 0 | O25: =N25*(1+Inputs!$C$29) -> 0 | ... Q25: =P25*(1+Inputs!$C$29) -> 0
A26: Net profit | C26: 16960 | D26: 17121 | E26: 21332 | F26: 23953 | G26: 27546 | H26: =H23-H24+H25 -> 0 | I26: =I23-I24+I25 -> 0 | J26: =J23-J24+J25 -> 0 | K26: =K23-K24+K25 -> 0 | L26: =L23-L24+L25 -> 0 | M26: =M23-M24+M25 -> 0 | N26: =N23-N24+N25 -> 0 | O26: =O23-O24+O25 -> 0 | ... Q26: =Q23-Q24+Q25 -> 0
A27: Minority share of profit | H27: =(H23-H24)*(Inputs!$C$18/($G38+$G39+Inputs!$C$18)) -> 0 | I27: =(I23-I24)*(Inputs!$C$18/($G38+$G39+Inputs!$C$18)) -> 0 | J27: =(J23-J24)*(Inputs!$C$18/($G38+$G39+Inputs!$C$18)) -> 0 | K27: =(K23-K24)*(Inputs!$C$18/($G38+$G39+Inputs!$C$18)) -> 0 | L27: =(L23-L24)*(Inputs!$C$18/($G38+$G39+Inputs!$C$18)) -> 0 | M27: =(M23-M24)*(Inputs!$C$18/($G38+$G39+Inputs!$C$18)) -> 0 | N27: =(N23-N24)*(Inputs!$C$18/($G38+$G39+Inputs!$C$18)) -> 0 | O27: =(O23-O24)*(Inputs!$C$18/($G38+$G39+Inputs!$C$18)) -> 0 | ... Q27: =(Q23-Q24)*(Inputs!$C$18/($G38+$G39+Inputs!$C$18)) -> 0
A28: Net profit to shareholders | H28: =H26-H27 -> 0 | I28: =I26-I27 -> 0 | J28: =J26-J27 -> 0 | K28: =K26-K27 -> 0 | L28: =L26-L27 -> 0 | M28: =M26-M27 -> 0 | N28: =N26-N27 -> 0 | O28: =O26-O27 -> 0 | ... Q28: =Q26-Q27 -> 0
A29: EPS (Rs) | C29: =C26/Inputs!$C$16 -> 0 | D29: =D26/Inputs!$C$16 -> 0 | E29: =E26/Inputs!$C$16 -> 0 | F29: =F26/Inputs!$C$16 -> 0 | G29: =G26/Inputs!$C$16 -> 0 | H29: =H28/Inputs!$C$16 -> 0 | I29: =I28/Inputs!$C$16 -> 0 | J29: =J28/Inputs!$C$16 -> 0 | K29: =K28/Inputs!$C$16 -> 0 | L29: =L28/Inputs!$C$16 -> 0 | M29: =M28/Inputs!$C$16 -> 0 | N29: =N28/Inputs!$C$16 -> 0 | O29: =O28/Inputs!$C$16 -> 0 | ... Q29: =Q28/Inputs!$C$16 -> 0
A30: Dividends | H30: =MAX(H28,0)*Inputs!$C$35 -> 0 | I30: =MAX(I28,0)*Inputs!$C$35 -> 0 | J30: =MAX(J28,0)*Inputs!$C$35 -> 0 | K30: =MAX(K28,0)*Inputs!$C$35 -> 0 | L30: =MAX(L28,0)*Inputs!$C$35 -> 0 | M30: =MAX(M28,0)*Inputs!$C$35 -> 0 | N30: =MAX(N28,0)*Inputs!$C$35 -> 0 | O30: =MAX(O28,0)*Inputs!$C$35 -> 0 | ... Q30: =MAX(Q28,0)*Inputs!$C$35 -> 0
A31: Balance sheet
A32: Net block | C32: 224923 | D32: 240424 | E32: 258934 | F32: 271437 | G32: 318697 | H32: =G32+H7-H21 -> 0 | I32: =H32+I7-I21 -> 0 | J32: =I32+J7-J21 -> 0 | K32: =J32+K7-K21 -> 0 | L32: =K32+L7-L21 -> 0 | M32: =L32+M7-M21 -> 0 | N32: =M32+N7-N21 -> 0 | O32: =N32+O7-O21 -> 0 | ... Q32: =P32+Q7-Q21 -> 0
A33: Capital work in progress | C33: 91126 | D33: 89179 | E33: 87664 | F33: 100859 | G33: 84957 | H33: =G33+H6-H7 -> 0 | I33: =H33+I6-I7 -> 0 | J33: =I33+J6-J7 -> 0 | K33: =J33+K6-K7 -> 0 | L33: =K33+L6-L7 -> 0 | M33: =L33+M6-M7 -> 0 | N33: =M33+N6-N7 -> 0 | O33: =N33+O6-O7 -> 0 | ... Q33: =P33+Q6-Q7 -> 0
A34: Investments | C34: 10626 | D34: 13935 | E34: 15885 | F34: 19704 | G34: 24180 | H34: =G34*(1+Inputs!$C$38)+H25 -> 0 | I34: =H34*(1+Inputs!$C$38)+I25 -> 0 | J34: =I34*(1+Inputs!$C$38)+J25 -> 0 | K34: =J34*(1+Inputs!$C$38)+K25 -> 0 | L34: =K34*(1+Inputs!$C$38)+L25 -> 0 | M34: =L34*(1+Inputs!$C$38)+M25 -> 0 | N34: =M34*(1+Inputs!$C$38)+N25 -> 0 | O34: =N34*(1+Inputs!$C$38)+O25 -> 0 | ... Q34: =P34*(1+Inputs!$C$38)+Q25 -> 0
A35: Other assets (non-cash) | C35: 89156 | D35: 103651 | E35: 116795 | F35: 131733 | G35: 130609 | H35: =H19*Inputs!$C$36 -> 0 | I35: =I19*Inputs!$C$36 -> 0 | J35: =J19*Inputs!$C$36 -> 0 | K35: =K19*Inputs!$C$36 -> 0 | L35: =L19*Inputs!$C$36 -> 0 | M35: =M19*Inputs!$C$36 -> 0 | N35: =N19*Inputs!$C$36 -> 0 | O35: =O19*Inputs!$C$36 -> 0 | ... Q35: =Q19*Inputs!$C$36 -> 0
A36: Incremental cash (floor, see revolver) | G36: 0 | H36: =H51+H52 -> 0 | I36: =I51+I52 -> 0 | J36: =J51+J52 -> 0 | K36: =K51+K52 -> 0 | L36: =L51+L52 -> 0 | M36: =M51+M52 -> 0 | N36: =N51+N52 -> 0 | O36: =O51+O52 -> 0 | ... Q36: =Q51+Q52 -> 0
A37: Total assets | C37: =C32+C33+C34+C35 -> 0 | D37: =D32+D33+D34+D35 -> 0 | E37: =E32+E33+E34+E35 -> 0 | F37: =F32+F33+F34+F35 -> 0 | G37: =G32+G33+G34+G35+G36 -> 0 | H37: =H32+H33+H34+H35+H36 -> 0 | I37: =I32+I33+I34+I35+I36 -> 0 | J37: =J32+J33+J34+J35+J36 -> 0 | K37: =K32+K33+K34+K35+K36 -> 0 | L37: =L32+L33+L34+L35+L36 -> 0 | M37: =M32+M33+M34+M35+M36 -> 0 | N37: =N32+N33+N34+N35+N36 -> 0 | ... Q37: =Q32+Q33+Q34+Q35+Q36 -> 0
A38: Equity capital | C38: 9697 | D38: 9697 | E38: 9697 | F38: 9697 | G38: 9697 | H38: =G38 -> 0 | I38: =H38 -> 0 | J38: =I38 -> 0 | K38: =J38 -> 0 | L38: =K38 -> 0 | M38: =L38 -> 0 | N38: =M38 -> 0 | O38: =N38 -> 0 | ... Q38: =P38 -> 0
A39: Reserves | C39: 125677 | D39: 137326 | E39: 151013 | F39: 174374 | G39: 193479 | H39: =G39+H28-H30 -> 0 | I39: =H39+I28-I30 -> 0 | J39: =I39+J28-J30 -> 0 | K39: =J39+K28-K30 -> 0 | L39: =K39+L28-L30 -> 0 | M39: =L39+M28-M30 -> 0 | N39: =M39+N28-N30 -> 0 | O39: =N39+O28-O30 -> 0 | ... Q39: =P39+Q28-Q30 -> 0
A40: Minority interest | G40: =Inputs!$C$18 -> 0 | H40: =G40+H27 -> 0 | I40: =H40+I27 -> 0 | J40: =I40+J27 -> 0 | K40: =J40+K27 -> 0 | L40: =K40+L27 -> 0 | M40: =L40+M27 -> 0 | N40: =M40+N27 -> 0 | O40: =N40+O27 -> 0 | ... Q40: =P40+Q27 -> 0
A41: Borrowings (term) | C41: 210707 | D41: 222913 | E41: 237131 | F41: 250096 | G41: 271005 | H41: =G41+H6*Inputs!$C$33 -> 0 | I41: =H41+I6*Inputs!$C$33 -> 0 | J41: =I41+J6*Inputs!$C$33 -> 0 | K41: =J41+K6*Inputs!$C$33 -> 0 | L41: =K41+L6*Inputs!$C$33 -> 0 | M41: =L41+M6*Inputs!$C$33 -> 0 | N41: =M41+N6*Inputs!$C$33 -> 0 | O41: =N41+O6*Inputs!$C$33 -> 0 | ... Q41: =P41+Q6*Inputs!$C$33 -> 0
...

Sheet DCF
A1: NTPC Ltd - valuation
A3: Cost of capital | C3: Value
A4: Risk-free (INR, G-sec less default spread) | C4: =Inputs!$C$4-Inputs!$C$5 -> 0
A5: Beta (Blume-adjusted) | C5: =0.67*Inputs!$C$11+0.33 -> 0
A6: Cost of equity | C6: =$C$4+$C$5*Inputs!$C$6 -> 0
A7: Post-tax cost of debt | C7: =Inputs!$C$12*(1-Inputs!$C$7) -> 0
A8: Borrowings FY26 | C8: =Model!$G$41 -> 0
A9: Market cap | C9: =Inputs!$C$15*Inputs!$C$16 -> 0
A10: Debt weight | C10: =$C$8/($C$8+$C$9) -> 0
A11: WACC | C11: =(1-$C$10)*$C$6+$C$10*$C$7 -> 0
A13: Free cash flow to firm | C13: FY27E | D13: FY28E | E13: FY29E | F13: FY30E | G13: FY31E | H13: FY32E | I13: FY33E | J13: FY34E | K13: FY35E | L13: FY36E
A14: NOPAT | C14: =(Model!$H$16-Model!$H$21)*(1-Inputs!$C$7) -> 0 | D14: =(Model!$I$16-Model!$I$21)*(1-Inputs!$C$7) -> 0 | E14: =(Model!$J$16-Model!$J$21)*(1-Inputs!$C$7) -> 0 | F14: =(Model!$K$16-Model!$K$21)*(1-Inputs!$C$7) -> 0 | G14: =(Model!$L$16-Model!$L$21)*(1-Inputs!$C$7) -> 0 | H14: =(Model!$M$16-Model!$M$21)*(1-Inputs!$C$7) -> 0 | I14: =(Model!$N$16-Model!$N$21)*(1-Inputs!$C$7) -> 0 | J14: =(Model!$O$16-Model!$O$21)*(1-Inputs!$C$7) -> 0 | K14: =(Model!$P$16-Model!$P$21)*(1-Inputs!$C$7) -> 0 | L14: =(Model!$Q$16-Model!$Q$21)*(1-Inputs!$C$7) -> 0
A15: Depreciation | C15: =Model!$H$21 -> 0 | D15: =Model!$I$21 -> 0 | E15: =Model!$J$21 -> 0 | F15: =Model!$K$21 -> 0 | G15: =Model!$L$21 -> 0 | H15: =Model!$M$21 -> 0 | I15: =Model!$N$21 -> 0 | J15: =Model!$O$21 -> 0 | K15: =Model!$P$21 -> 0 | L15: =Model!$Q$21 -> 0
A16: Capex | C16: =-Model!$H$6 -> 0 | D16: =-Model!$I$6 -> 0 | E16: =-Model!$J$6 -> 0 | F16: =-Model!$K$6 -> 0 | G16: =-Model!$L$6 -> 0 | H16: =-Model!$M$6 -> 0 | I16: =-Model!$N$6 -> 0 | J16: =-Model!$O$6 -> 0 | K16: =-Model!$P$6 -> 0 | L16: =-Model!$Q$6 -> 0
A17: Increase in NWC | C17: =-Model!$H$47 -> 0 | D17: =-Model!$I$47 -> 0 | E17: =-Model!$J$47 -> 0 | F17: =-Model!$K$47 -> 0 | G17: =-Model!$L$47 -> 0 | H17: =-Model!$M$47 -> 0 | I17: =-Model!$N$47 -> 0 | J17: =-Model!$O$47 -> 0 | K17: =-Model!$P$47 -> 0 | L17: =-Model!$Q$47 -> 0
A18: FCFF | C18: =SUM(C14:C17) -> 0 | D18: =SUM(D14:D17) -> 0 | E18: =SUM(E14:E17) -> 0 | F18: =SUM(F14:F17) -> 0 | G18: =SUM(G14:G17) -> 0 | H18: =SUM(H14:H17) -> 0 | I18: =SUM(I14:I17) -> 0 | J18: =SUM(J14:J17) -> 0 | ... L18: =SUM(L14:L17) -> 0
A19: FCFF (stub-adjusted) | C19: =C18*Inputs!$C$8 -> 0 | D19: =D18*1 -> 0 | E19: =E18*1 -> 0 | F19: =F18*1 -> 0 | G19: =G18*1 -> 0 | H19: =H18*1 -> 0 | I19: =I18*1 -> 0 | J19: =J18*1 -> 0 | K19: =K18*1 -> 0 | L19: =L18*1 -> 0
A20: Discount period (yrs) | C20: =Inputs!$C$8+0 -> 0 | D20: =Inputs!$C$8+1 -> 0 | E20: =Inputs!$C$8+2 -> 0 | F20: =Inputs!$C$8+3 -> 0 | G20: =Inputs!$C$8+4 -> 0 | H20: =Inputs!$C$8+5 -> 0 | I20: =Inputs!$C$8+6 -> 0 | J20: =Inputs!$C$8+7 -> 0 | K20: =Inputs!$C$8+8 -> 0 | L20: =Inputs!$C$8+9 -> 0
A21: Discount factor | C21: =1/(1+DCF!$C$11)^C20 -> 0 | D21: =1/(1+DCF!$C$11)^D20 -> 0 | E21: =1/(1+DCF!$C$11)^E20 -> 0 | F21: =1/(1+DCF!$C$11)^F20 -> 0 | G21: =1/(1+DCF!$C$11)^G20 -> 0 | H21: =1/(1+DCF!$C$11)^H20 -> 0 | I21: =1/(1+DCF!$C$11)^I20 -> 0 | J21: =1/(1+DCF!$C$11)^J20 -> 0 | ... L21: =1/(1+DCF!$C$11)^L20 -> 0
A22: PV of FCFF | C22: =C19*C21 -> 0 | D22: =D19*D21 -> 0 | E22: =E19*E21 -> 0 | F22: =F19*F21 -> 0 | G22: =G19*G21 -> 0 | H22: =H19*H21 -> 0 | I22: =I19*I21 -> 0 | J22: =J19*J21 -> 0 | ... L22: =L19*L21 -> 0
A25: PV of explicit FCFF | C25: =SUM(C22:L22) -> 0
A26: Terminal value (value-driver) | C26: =L14*(1+Inputs!$C$13)*(1-Inputs!$C$13/Inputs!$C$14)/(DCF!$C$11-Inputs!$C$13) -> 0
A27: PV of terminal value | C27: =$C$26/(1+DCF!$C$11)^L20 -> 0
A28: Enterprise value | C28: =$C$25+$C$27 -> 0
A29: Less: borrowings FY26 | C29: =-Model!$G$41 -> 0
A30: Add: cash | C30: =Inputs!$C$17 -> 0
A31: Add: investments (book) | C31: =Model!$G$34 -> 0
A32: Less: minority interest | C32: =-Inputs!$C$18 -> 0
A33: Equity value today | C33: =SUM($C$28,$C$29,$C$30,$C$31,$C$32) -> 0
A34: DCF value per share today (Rs) | C34: =$C$33/Inputs!$C$16 -> 0
A35: Terminal value share of EV | C35: =$C$27/$C$28 -> 0
A36: DCF value in 12 months (grown at Ke, less FY27 DPS) | C36: =$C$34*(1+DCF!$C$6)-Model!$H$30/Inputs!$C$16 -> 0
A37: Peer EV/EBITDA x FY27E EBITDA | C37: =Inputs!$C$19*Model!$H$16 -> 0
A38: EV/EBITDA value in 12 months (Rs) | C38: =($C$37-Model!$H$41-Model!$H$42+Inputs!$C$17+Model!$H$36-Model!$H$40)/Inputs!$C$16 -> 0
A39: SOTP value per share (Rs, regulated only) | C39: =SOTP!$C$30 -> 0
A40: 12-month target price (Rs) | C40: =$C$39 -> 0
A41: Upside / (downside) | C41: =$C$40/Inputs!$C$15-1 -> 0
A42: Rating | C42: =IF($C$41>0.15,"BUY",IF($C$41<-0.1,"SELL","HOLD")) -> 0
A45: DCF value per share today: WACC (rows) x terminal growth (cols)
C46: 0.04 | D46: 0.045 | E46: 0.05 | F46: 0.055 | G46: 0.06
...

Sheet SOTP
A1: NTPC Ltd - sum of the parts at Mar-27
A3: Residual income on regulated equity
B4: t | C4: FY27E | D4: FY28E | E4: FY29E | F4: FY30E | G4: FY31E | H4: FY32E | I4: FY33E | J4: FY34E | K4: FY35E | L4: FY36E
A5: Regulated equity (closing) | C5: =Model!$H$14 -> 0 | D5: =Model!$I$14 -> 0 | E5: =Model!$J$14 -> 0 | F5: =Model!$K$14 -> 0 | G5: =Model!$L$14 -> 0 | H5: =Model!$M$14 -> 0 | I5: =Model!$N$14 -> 0 | J5: =Model!$O$14 -> 0 | K5: =Model!$P$14 -> 0 | L5: =Model!$Q$14 -> 0
A6: Residual income (RoE - Ke) x opening | D6: =(Inputs!$C$42-DCF!$C$6)*C5 -> 0 | E6: =(Inputs!$C$42-DCF!$C$6)*D5 -> 0 | F6: =(Inputs!$C$42-DCF!$C$6)*E5 -> 0 | G6: =(Inputs!$C$42-DCF!$C$6)*F5 -> 0 | H6: =(Inputs!$C$42-DCF!$C$6)*G5 -> 0 | I6: =(Inputs!$C$42-DCF!$C$6)*H5 -> 0 | J6: =(Inputs!$C$42-DCF!$C$6)*I5 -> 0 | K6: =(Inputs!$C$42-DCF!$C$6)*J5 -> 0 | L6: =(Inputs!$C$42-DCF!$C$6)*K5 -> 0
A7: Discount factor | D7: =1/(1+DCF!$C$6)^1 -> 0 | E7: =1/(1+DCF!$C$6)^2 -> 0 | F7: =1/(1+DCF!$C$6)^3 -> 0 | G7: =1/(1+DCF!$C$6)^4 -> 0 | H7: =1/(1+DCF!$C$6)^5 -> 0 | I7: =1/(1+DCF!$C$6)^6 -> 0 | J7: =1/(1+DCF!$C$6)^7 -> 0 | K7: =1/(1+DCF!$C$6)^8 -> 0 | L7: =1/(1+DCF!$C$6)^9 -> 0
A8: PV | D8: =D6*D7 -> 0 | E8: =E6*E7 -> 0 | F8: =F6*F7 -> 0 | G8: =G6*G7 -> 0 | H8: =H6*H7 -> 0 | I8: =I6*I7 -> 0 | J8: =J6*J7 -> 0 | K8: =K6*K7 -> 0 | L8: =L6*L7 -> 0
A11: Regulated equity FY27E (book) | C11: =$C$5 -> 0
A12: PV of residual income FY28-FY36 | C12: =SUM(D8:L8) -> 0
A13: PV of terminal residual income | C13: =(Inputs!$C$42-DCF!$C$6)*L5/(DCF!$C$6-Inputs!$C$43)/(1+DCF!$C$6)^9 -> 0
A14: Regulated equity value | C14: =SUM(C11:C13) -> 0
A15: Implied P/B on FY27E regulated equity | C15: =C14/C11 -> 0
A16: Equity in regulated CWIP at book | C16: =Inputs!$C$41*(1-Inputs!$C$21)*Model!$H$33 -> 0
A17: NTPC Green stake at market less holdco discount | C17: =Inputs!$C$45*Inputs!$C$44*(1-Inputs!$C$46) -> 0
A29: Equity value | C29: =C14+C16+C17 -> 0
A30: SOTP value per share (Rs) | C30: =C29/Inputs!$C$16 -> 0
A32: JVs are not added: consolidated regulated equity already includes them.

Sheet Comps
A1: Listed power comps, FY26A
A3: Company | B3: Segment | C3: Mcap | D3: EV | E3: EV/EBITDA | F3: P/E | G3: P/B | H3: ROE | I3: EBITDA margin | J3: ND/EBITDA
A4: Adani Power | B4: IPP / thermal | C4: 395818.36 | D4: 449561.84 | E4: 22.698265 | F4: 30.515639 | G4: 6.0954211 | H4: 0.21389466 | I4: 0.36514814 | J4: 2.6395254
A5: NTPC Ltd | B5: Integrated / thermal-led | C5: 326166.76 | D5: 598699.47 | E5: 10.799442 | F5: 11.840803 | G5: 1.605341 | H5: 0.14226579 | I5: 0.29585079 | J5: 4.7720935
A6: Power Grid Corp | B6: Transmission / PSU | C6: 247442.56 | D6: 390580.25 | E6: 11.896691 | F6: 15.535068 | G6: 2.4622621 | H6: 0.16492283 | I6: 0.70252284 | J6: 4.3598334
A7: Adani Green Energy | B7: Renewables | C7: 222039.35 | D7: 331425.35 | E7: 30.730213 | F7: 111.74602 | G7: 11.12143 | H7: 0.12379291 | I7: 0.83423577 | J7: 9.2231803
A8: Tata Power | B8: Integrated / private | C8: 122077.95 | D8: 200524.02 | E8: 15.10994 | F8: 23.852667 | G8: 3.0930867 | H8: 0.13592001 | I8: 0.21257749 | J8: 5.302932
A9: JSW Energy | B9: IPP / private | C9: 102612.88 | D9: 174275.72 | E9: 17.309865 | F9: 37.15166 | G9: 3.3368959 | H9: 0.095057819 | I9: 0.53267023 | J9: 6.837206
A10: NHPC | B10: Hydro / PSU | C10: 77246.318 | D10: 133013.44 | E10: 32.466058 | F10: 18.304815 | G10: 1.864187 | H10: 0.10406263 | I10: 0.35273353 | J10: 11.91102
A11: Torrent Power | B11: Integrated / private | C11: 65966.013 | D11: 78251.023 | E11: 14.031024 | F11: 26.717705 | G11: 3.4582444 | H11: 0.13458708 | I11: 0.19253608 | J11: 2.0892218
A12: NLC India | B12: Lignite-thermal / PSU | C12: 38151.92 | D12: 69079.81 | E12: 12.428897 | F12: 10.122558 | G12: 1.7724469 | H12: 0.18728881 | I12: 0.31725555 | J12: 4.8900036
A13: SJVN | B13: Hydro / PSU | C13: 26270.681 | D13: 56423.111 | E13: 16.787596 | F13: 40.920063 | G13: 1.8449807 | H13: 0.045182631 | I13: 0.74227032 | J13: 8.9681791
A14: CESC | B14: Integrated / private | C14: 21453.032 | D14: 38179.032 | E14: 10.535053 | F14: 13.258981 | G14: 1.7121334 | H14: 0.13186634 | I14: 0.19515347 | J14: 4.4336341
A15: JP Power Ventures | B15: IPP / thermal | C15: 11918.165 | D15: 14554.215 | E15: 10.646829 | F15: 26.426086 | G15: 0.93607956 | H15: 0.036061248 | I15: 0.24573072 | J15: 1.9283467
A16: Reliance Power | B16: IPP / thermal | C16: 9504.0017 | D16: 23811.752 | E16: 10.068394 | G16: 0.59251881 | H16: -0.020817247 | I16: 0.31036745 | J16: 6.0497886
A17: PTC India | B17: Power trading | C17: 4779.6464 | D17: 3041.2064 | E17: 3.4094242 | F17: 6.6661734 | G17: 0.79913833 | H17: 0.12166978 | I17: 0.053187049 | J17: -3.1571973

Sheet Guidance
A1: Management guidance extracted from earnings calls (NSE filings)
A3: Call | B3: Page | C3: Figures | D3: Sentence
A4: Q1FY27 | B4: 5 | C4: 20%; 21% | D4: And our share of electricity, which is around 20%, 21%, is increasing, and in coming days it will be much higher, which is giving a lot of confidence that we will be growing at a much faster rate.
A5: Q1FY27 | B5: 10 | C5: 1,08,000 crore | D5: Group-level capex is INR1,08,000 crores estimates.
A6: Q1FY27 | B6: 10 | C6: 9,63,000 crore | D6: We'll see a major shift towards nuclear power as well, while continuing with the RE project as well, with an approximately INR9,63,000 crores as capex.
A7: Q1FY27 | B7: 10 | C7: 17 lakh crore | D7: So, the total capex envisaged is INR17 lakh crores, as CMD sir was mentioning, over the next 11 years, that is up to financial year 37.
A8: Q1FY27 | B8: 10 | C8: 60 gigawatt; 136 gigawatt | D8: Our renewable portfolio is targeted to reach 60 gigawatts by FY32 and expand further to 136 gigawatts by FY37.
A9: Q1FY27 | B9: 10 | C9: 4.2 gigawatt; 7 gigawatt; 8 gigawatt | D9: During FY26, we have added around 4.2 gigawatt, and further, subject to transmission infrastructure, we are targeting to add another 7 gigawatts to 8 gigawatts for the renewable capacity in FY27.
A10: Q1FY27 | B10: 10 | C10: 1.8 gigawatt | D10: A further 1.8 gigawatt-hours of BESS projects are under planning to strengthen our near-term storage portfolio.
A11: Q1FY27 | B11: 10 | C11: 30.4 gigawatt; 18.6 gigawatt | D11: Beyond this, NTPC is developing a substantial non-solar hour BESS pipeline of 30.4 gigawatt-hours, of which 18.6 gigawatt-hours have already been tendered.
A12: Q1FY27 | B12: 10 | C12: 30 gigawatt | D12: Coming to newer frontiers, steps being undertaken on the nuclear front, we have an ambitious goal of installing 30 gigawatts of nuclear capacity by FY47.
A13: Q1FY27 | B13: 11 | C13: 13.2 gigawatt; 5 gigawatt; 6 gigawatt | D13: We have been allocated 13.2 gigawatt of PSP project across Tamil Nadu, Maharashtra, Chhattisgarh, Madhya Pradesh, and Odisha, and we aim to commission 3 to 5 gigawatt of capacity by FY33 and nearly 6 gigawatt by FY2037.
A14: Q1FY27 | B14: 11 | C14: 1 lakh crore | D14: Spread across 1,200 acres with an envisaged investment of around INR 1 lakh crores, the project will create an integrated ecosystem encompassing hydrogen production, derivative manufacturing, and export infrastructure, producing green chemicals such as green methanol, ammonia, ethanol, sustainable aviation fuel, and green urea.
A15: Q1FY27 | B15: 14 | C15: 250 gigawatt | D15: As we lead India's energy transition, we are balancing growth with sustainability, innovation with reliability, and ambition with disciplined execution, with a clear path to 250 gigawatt by FY37 and a diversified portfolio spanning conventional, renewable, nuclear, and emerging energy businesses.
... A153: Q1FY26 | B153: 14 | C153: 27 gigawatt; 62 gigawatt | D153: CMD: So, I did mention to you that we will be having 26 to 27 gigawatt addition to around 62 gigawatt, whatever it is commissioned.
